<?xml version="1.0" encoding="utf-8"?>
<!-- This URDF was automatically created by SolidWorks to URDF Exporter! Originally created by Stephen Brawner (brawner@gmail.com) 
     Commit Version: 1.6.0-4-g7f85cfe  Build Version: 1.6.7995.38578
     For more information, please see http://wiki.ros.org/sw_urdf_exporter -->
<robot
  name="dm_arm_v2_R">
  <link
    name="world_R">
  </link>
  <joint name="base_joint_R" type="fixed">
  <parent link="world_R"/>
  <child link="base_link_R"/>
  <origin xyz="0 0 0" rpy="0 0 0"/> <!-- 绕 Y 轴旋转 -90°，侧装 -->
  </joint>
  <link
    name="base_link_R">
    <inertial>
      <origin
        xyz="-4.0721E-05 0.027295 4.0705E-05"
        rpy="0 0 0" />
      <mass
        value="0.458" />
      <inertia
        ixx="0.00010877"
        ixy="-1.336E-07"
        ixz="1.0688E-07"
        iyy="9.6342E-05"
        iyz="1.3354E-07"
        izz="0.00010533" />
    </inertial>
    <visual>
      <origin
        xyz="0 0 0"
        rpy="0 0 0" />
      <geometry>
        <mesh
          filename="package://dm_arm_v2_r/meshes/base_link.STL" />
      </geometry>
      <material
        name="">
        <color
          rgba="1 1 1 1" />
      </material>
    </visual>
    <collision>
      <origin
        xyz="0 0 0"
        rpy="0 0 0" />
      <geometry>
        <mesh
          filename="package://dm_arm_v2_r/meshes/base_link.STL" />
      </geometry>
    </collision>
  </link>
  <link
    name="link1_R">
    <inertial>
      <origin
        xyz="0.022488 -2.9766E-13 0.020137"
        rpy="0 0 0" />
      <mass
        value="0.066" />
      <inertia
        ixx="1.8229E-05"
        ixy="5.4306E-17"
        ixz="-4.6522E-06"
        iyy="1.9438E-05"
        iyz="6.0125E-17"
        izz="8.0563E-06" />
    </inertial>
    <visual>
      <origin
        xyz="0 0 0"
        rpy="0 0 0" />
      <geometry>
        <mesh
          filename="package://dm_arm_v2_r/meshes/link1.STL" />
      </geometry>
      <material
        name="">
        <color
          rgba="1 1 1 1" />
      </material>
    </visual>
    <collision>
      <origin
        xyz="0 0 0"
        rpy="0 0 0" />
      <geometry>
        <mesh
          filename="package://dm_arm_v2_r/meshes/link1.STL" />
      </geometry>
    </collision>
  </link>
  <joint
    name="joint1_R"
    type="revolute">
    <origin
      xyz="0 0 0.06625"
      rpy="0 0 0" />
    <parent
      link="base_link_R" />
    <child
      link="link1_R" />
    <axis
      xyz="0 0 1" />
    <limit
      lower="-2.967"
      upper="2.967"
      effort="0"
      velocity="0" />
  </joint>
  <link
    name="link2_R">
    <inertial>
      <origin
        xyz="-2.8959E-05 -0.12763 0.005453"
        rpy="0 0 0" />
      <mass
        value="0.924" />
      <inertia
        ixx="0.0051182"
        ixy="1.2408E-06"
        ixz="1.8886E-07"
        iyy="0.00018206"
        iyz="1.8896E-07"
        izz="0.0050618" />
    </inertial>
    <visual>
      <origin
        xyz="0 0 0"
        rpy="0 0 0" />
      <geometry>
        <mesh
          filename="package://dm_arm_v2_r/meshes/link2.STL" />
      </geometry>
      <material
        name="">
        <color
          rgba="1 1 1 1" />
      </material>
    </visual>
    <collision>
      <origin
        xyz="0 0 0"
        rpy="0 0 0" />
      <geometry>
        <mesh
          filename="package://dm_arm_v2_r/meshes/link2.STL" />
      </geometry>
    </collision>
  </link>
  <joint
    name="joint2_R"
    type="revolute">
    <origin
      xyz="0 0 0.0532"
      rpy="-1.5708 0 1.5708" />
    <parent
      link="link1_R" />
    <child
      link="link2_R" />
    <axis
      xyz="0 0 -1" />
    <limit
      lower="-1.57"
      upper="1.57"
      effort="0"
      velocity="0" />
  </joint>
  <link
    name="link3_R">
    <inertial>
      <origin
        xyz="-4.9758E-09 -0.096929 -0.0047145"
        rpy="0 0 0" />
      <mass
        value="0.385" />
      <inertia
        ixx="7.8869E-05"
        ixy="-1.8361E-11"
        ixz="2.4381E-11"
        iyy="5.2998E-05"
        iyz="7.4401E-06"
        izz="7.6953E-05" />
    </inertial>
    <visual>
      <origin
        xyz="0 0 0"
        rpy="0 0 0" />
      <geometry>
        <mesh
          filename="package://dm_arm_v2_r/meshes/link3.STL" />
      </geometry>
      <material
        name="">
        <color
          rgba="1 1 1 1" />
      </material>
    </visual>
    <collision>
      <origin
        xyz="0 0 0"
        rpy="0 0 0" />
      <geometry>
        <mesh
          filename="package://dm_arm_v2_r/meshes/link3.STL" />
      </geometry>
    </collision>
  </link>
  <joint
    name="joint3_R"
    type="revolute">
    <origin
      xyz="0 -0.2552 0"
      rpy="0 0 0" />
    <parent
      link="link2_R" />
    <child
      link="link3_R" />
    <axis
      xyz="0 0 1" />
    <limit
      lower="-1.57"
      upper="1.57"
      effort="0"
      velocity="0" />
  </joint>
  <link
    name="link4_R">
    <inertial>
      <origin
        xyz="-1.4549E-12 -0.018351 0.020683"
        rpy="0 0 0" />
      <mass
        value="0.056" />
      <inertia
        ixx="1.5419E-05"
        ixy="-2.9866E-16"
        ixz="-2.6865E-16"
        iyy="1.4928E-05"
        iyz="3.4555E-06"
        izz="5.8052E-06" />
    </inertial>
    <visual>
      <origin
        xyz="0 0 0"
        rpy="0 0 0" />
      <geometry>
        <mesh
          filename="package://dm_arm_v2_r/meshes/link4.STL" />
      </geometry>
      <material
        name="">
        <color
          rgba="1 1 1 1" />
      </material>
    </visual>
    <collision>
      <origin
        xyz="0 0 0"
        rpy="0 0 0" />
      <geometry>
        <mesh
          filename="package://dm_arm_v2_r/meshes/link4.STL" />
      </geometry>
    </collision>
  </link>
  <joint
    name="joint4_R"
    type="revolute">
    <origin
      xyz="0 -0.1372 0"
      rpy="1.5708 0 0" />
    <parent
      link="link3_R" />
    <child
      link="link4_R" />
    <axis
      xyz="0 0 -1" />
    <limit
      lower="-2.967"
      upper="2.967"
      effort="0"
      velocity="0" />
  </joint>
  <link
    name="link5_R">
    <inertial>
      <origin
        xyz="-2.1939E-09 -0.030604 0.0013068"
        rpy="0 0 0" />
      <mass
        value="0.652" />
      <inertia
        ixx="9.4517E-05"
        ixy="8.644E-12"
        ixz="9.584E-12"
        iyy="9.6472E-05"
        iyz="2.6532E-06"
        izz="9.3688E-05" />
    </inertial>
    <visual>
      <origin
        xyz="0 0 0"
        rpy="0 0 0" />
      <geometry>
        <mesh
          filename="package://dm_arm_v2_r/meshes/link5.STL" />
      </geometry>
      <material
        name="">
        <color
          rgba="1 1 1 1" />
      </material>
    </visual>
    <collision>
      <origin
        xyz="0 0 0"
        rpy="0 0 0" />
      <geometry>
        <mesh
          filename="package://dm_arm_v2_r/meshes/link5.STL" />
      </geometry>
    </collision>
  </link>
  <joint
    name="joint5_R"
    type="revolute">
    <origin
      xyz="0 0 0.0496"
      rpy="-1.5708 0 0" />
    <parent
      link="link4_R" />
    <child
      link="link5_R" />
    <axis
      xyz="0 0 -1" />
    <limit
      lower="-1.57"
      upper="1.57"
      effort="0"
      velocity="0" />
  </joint>
  <link
    name="link6_R">
    <inertial>
      <origin
        xyz="-0.012978 -0.00042483 0.021604"
        rpy="0 0 0" />
      <!-- <mass
        value="0.585" /> -->
      <mass
        value="0.00" />
      <inertia
        ixx="0.00020761"
        ixy="-5.7794E-06"
        ixz="-8.5177E-06"
        iyy="0.0004167"
        iyz="4.0184E-07"
        izz="0.00053787" />
    </inertial>
    <visual>
      <origin
        xyz="0 0 0"
        rpy="0 0 0" />
      <geometry>
        <mesh
          filename="package://dm_arm_v2_r/meshes/link6.STL" />
      </geometry>
      <material
        name="">
        <color
          rgba="1 1 1 1" />
      </material>
    </visual>
    <collision>
      <origin
        xyz="0 0 0"
        rpy="0 0 0" />
      <geometry>
        <mesh
          filename="package://dm_arm_v2_r/meshes/link6.STL" />
      </geometry>
    </collision>
  </link>
  <joint
    name="joint6_R"
    type="revolute">
    <origin
      xyz="0 -0.086 0"
      rpy="1.5708 0 0" />
    <parent
      link="link5_R" />
    <child
      link="link6_R" />
    <axis
      xyz="0 0 -1" />
    <limit
      lower="-2.967"
      upper="2.967"
      effort="0"
      velocity="0" />
  </joint>
  <!-- <link
    name="endlink1_R">
    <inertial>
      <origin
        xyz="0.02673 -0.015825 -0.003082"
        rpy="0 0 0" />
      <mass
        value="0.000" />
      <inertia
        ixx="6.6291E-07"
        ixy="4.4759E-07"
        ixz="-1.125E-08"
        iyy="7.2907E-07"
        iyz="8.2847E-09"
        izz="1.1012E-06" />
    </inertial>
    <visual>
      <origin
        xyz="0 0 0"
        rpy="0 0 0" />
      <geometry>
        <mesh
          filename="package://dm_arm_v2_r/meshes/endlink1.STL" />
      </geometry>
      <material
        name="">
        <color
          rgba="1 1 1 1" />
      </material>
    </visual>
    <collision>
      <origin
        xyz="0 0 0"
        rpy="0 0 0" />
      <geometry>
        <mesh
          filename="package://dm_arm_v2_r/meshes/endlink1.STL" />
      </geometry>
    </collision>
  </link>
  <joint
    name="joint7_R"
    type="prismatic">
    <origin
      xyz="-0.02405 -0.044 0.024"
      rpy="-1.5708 0 3.1416" />
    <parent
      link="link6_R" />
    <child
      link="endlink1_R" />
    <axis
      xyz="0 0 -1" />
    <limit
      lower="0"
      upper="0.02"
      effort="0"
      velocity="0" />
  </joint>
  <link
    name="endlink2_R">
    <inertial>
      <origin
        xyz="0.065425 -0.010042 0.0031713"
        rpy="0 0 0" />
      <mass
        value="0.00" />
      <inertia
        ixx="1.0349E-06"
        ixy="1.9324E-06"
        ixz="5.704E-08"
        iyy="6.2013E-06"
        iyz="-9.7237E-09"
        izz="6.922E-06" />
    </inertial>
    <visual>
      <origin
        xyz="0 0 0"
        rpy="0 0 0" />
      <geometry>
        <mesh
          filename="package://dm_arm_v2_r/meshes/endlink2.STL" />
      </geometry>
      <material
        name="">
        <color
          rgba="1 1 1 1" />
      </material>
    </visual>
    <collision>
      <origin
        xyz="0 0 0"
        rpy="0 0 0" />
      <geometry>
        <mesh
          filename="package://dm_arm_v2_r/meshes/endlink2.STL" />
      </geometry>
    </collision>
  </link>
  <joint
    name="joint8_R"
    type="prismatic">
    <origin
      xyz="0.0378 0.044 0.024"
      rpy="-1.5708 0 -3.1416" />
    <parent
      link="link6_R" />
    <child
      link="endlink2_R" />
    <axis
      xyz="0 0 1" />
    <limit
      lower="0"
      upper="0"
      effort="0"
      velocity="0" />
    <mimic
      joint="joint7_R"
      multiplier="1"
      offset="0" />
  </joint> -->
</robot>
